<?xml version="1.0"?>
<robot name="erp42" xmlns:xacro="http://ros.org/wiki/xacro">
<!-- Constants for robot dimensions -->
  <xacro:property name="wheel_radius" value="0.28" /> <!-- wheel radius for collision -->
  <xacro:property name="wheel_length" value="0.15" /> <!-- wheel length for collision -->
  <xacro:property name="wheel_mass" value="5" /> <!-- wheel mass -->
  <xacro:property name="wheel_coefficient_friction" value="0.72" /> <!-- coefficiente friction rubber -->
  <xacro:property name="disk_radius" value="0.1" /> <!-- disk radius for collision -->
  <xacro:property name="disk_length" value="0.03" /> <!-- disk length for collision -->
  <xacro:property name="disk_mass" value="2" /> <!-- disk mass -->
  <xacro:property name="camera_size" value="0.05" /> <!-- Size of square 'camera' box -->
  <xacro:property name="camera_mass" value="1e-5" /> <!-- mass of camera -->
<!-- XXXXXXXXXXXXXXXXXXXXXXXXXXXXXXXXXXXXXXXXXX  LINK  XXXXXXXXXXXXXXXXXXXXXXXXXXXXXXXXXXXXXXXXXXXXXXXXX-->
 <macro name="wheel" params="prefix suffix x y z pitch yall">
  <link name="${prefix}_${suffix}_wheel">
    <visual>
    <origin xyz="${x} ${y} ${z}" rpy="1.5707 ${pitch} ${yall}" />
      <geometry>
       <mesh filename="package://erp42/meshes/caucho.dae" scale="1 1 1"/>
      </geometry>
    </visual>

  <collision>
      <geometry>
       <cylinder radius="${wheel_radius}" length="${wheel_length}"/> 
      </geometry>
        <origin xyz="0 0 0" rpy="1.5707 0 0" />
  </collision>
        
   <inertial>
      <mass value="${wheel_mass}" />
      <origin xyz="0 0 0" rpy="1.5707 0 0" />
      <inertia ixx="1.0" ixy="0.0" ixz="0.0" iyy="1.0" iyz="0.0" izz="1.0" />
    </inertial>
  </link>

  <gazebo reference="${prefix}_${suffix}_wheel">
    <mu1 value="${wheel_coefficient_friction}"/>
    <mu2 value="${wheel_coefficient_friction}"/>
    <kp value="10000000.0" />
    <kd value="1.0" />
    <material>Gazebo/Grey</material>
  </gazebo>

   <transmission name="${prefix}_${suffix}_wheel_trans">
      <type>transmission_interface/SimpleTransmission</type>
      <actuator name="${prefix}_${suffix}_wheel_motor">
        <hardwareInterface>hardware_interface/EffortJointInterface</hardwareInterface>
        <!--<hardwareInterface>hardware_interface/VelocityJointInterface</hardwareInterface>-->
        <mechanicalReduction>1</mechanicalReduction>
      </actuator>
      <joint name="${prefix}_${suffix}_wheel_joint">
        <hardwareInterface>hardware_interface/EffortJointInterface</hardwareInterface>
        <!--<hardwareInterface>hardware_interface/VelocityJointInterface</hardwareInterface>-->
      </joint>
    </transmission>
 </macro>
 <!-- XXXXXXXXXXXXXXXXXXXXXXXXXXXXXXXXXXXXXXX  actuator 1 2 front  XXXXXXXXXXXXXXXXXXXXXXXXXXXXXXXXXXXXXXXX-->
  <macro name="wheel_front_joint" params="prefix suffix x y z ">
   <joint name="${prefix}_${suffix}_wheel_joint" type="continuous">
      <axis xyz="0 1 0" />
      <parent link="${prefix}_${suffix}_disk_wheel"/>
      <child link="${prefix}_${suffix}_wheel"/>
      <origin xyz="${x} ${y} ${z}" />
   </joint>
  </macro>
   <!-- XXXXXXXXXXXXXXXXXXXXXXXXXXXXXXXXXXXXXXX  actuator 3 4 back  XXXXXXXXXXXXXXXXXXXXXXXXXXXXXXXXXXXXXXXX-->
  <macro name="wheel_back_joint" params="prefix suffix x y z ">
   <joint name="${prefix}_${suffix}_wheel_joint" type="continuous">
      <axis xyz="0 1 0" />
      <parent link="${prefix}_${suffix}_disk_wheel"/>
      <child link="${prefix}_${suffix}_wheel"/>
      <origin xyz="${x} ${y} ${z}" />
   </joint>
  </macro>
<!-- XXXXXXXXXXXXXXXXXXXXXXXXXXXXXXXXXXXXXXXXXX  DISK LINK  XXXXXXXXXXXXXXXXXXXXXXXXXXXXXXXXXXXXXXXXXXXXXXXXX-->
 <macro name="disk_wheel" params="prefix suffix roll pitch yall">  
  <link name="${prefix}_${suffix}_disk_wheel">
    <visual>
    <origin xyz="0 0 0" rpy="${roll} ${pitch} ${yall}" />
      <geometry>
        <mesh filename="package://erp42/meshes/disk.dae" scale="1 1 1"/>
      </geometry>
    </visual>

    <collision>
      <geometry>
      <cylinder radius="${disk_radius}" length="${disk_length}"/> 
      </geometry>
        <origin xyz="0 0 0" rpy="1.5707 0 0"  />
    </collision>
        
    <inertial>
      <mass value="${disk_mass}"/>
      <origin xyz="0 0 0" rpy="${roll} ${pitch} ${yall}" />
      <inertia ixx="1.0" ixy="0" ixz="0" iyy="1.0" iyz="0" izz="1.0"/>
    </inertial>
  </link>

  <gazebo reference="${prefix}_${suffix}_disk_wheel">
    <material>Gazebo/Green</material>
    <mu1>0.8</mu1>
    <mu2>0.8</mu2>
  </gazebo>

  <transmission name="${prefix}_${suffix}_disk_wheel_trans">
      <type>transmission_interface/SimpleTransmission</type>
      <actuator name="${prefix}_${suffix}_disk_wheel_motor">
        <mechanicalReduction>1</mechanicalReduction>
        <hardwareInterface>hardware_interface/PositionJointInterface</hardwareInterface>
      </actuator>
      <joint name="${prefix}_${suffix}_disk_wheel_joint">
        <hardwareInterface>hardware_interface/PositionJointInterface</hardwareInterface>
      </joint>
    </transmission>
 </macro>

 <!-- XXXXXXXXXXXXXXXXXXXXXXXXXXXXXXXXXXXXXXXXXX  DISK back LINK  XXXXXXXXXXXXXXXXXXXXXXXXXXXXXXXXXXXXXXXXXXXXXXXXX-->
 <macro name="disk_back_wheel" params="prefix suffix roll pitch yall">  
  <link name="${prefix}_${suffix}_disk_wheel">
    <visual>
    <origin xyz="0 0 0" rpy="${roll} ${pitch} ${yall}" />
      <geometry>
        <mesh filename="package://erp42/meshes/disk.dae" scale="1 1 1"/>
      </geometry>
    </visual>
<collision>
      <geometry>
      <cylinder radius="${disk_radius}" length="${disk_length}"/> 
      </geometry>
        <origin xyz="0 0 0" rpy="1.5707 0 0"  />
    </collision>
        
    <inertial>
      <mass value="${disk_mass}"/>
      <origin xyz="0 0 0" rpy="${roll} ${pitch} ${yall}" />
      <inertia ixx="1.0" ixy="0" ixz="0" iyy="1.0" iyz="0" izz="1.0"/>
    </inertial>
  </link>

  <gazebo reference="${prefix}_${suffix}_disk_wheel">
    <material>Gazebo/Green</material>
    <mu1>0.8</mu1>
    <mu2>0.8</mu2>
  </gazebo>
</macro>

 <!-- XXXXXXXXXXXXXXXXXXXXXXXXXXXXXXXXXXXXXXXXX  actuator 5, 6  XXXXXXXXXXXXXXXXXXXXXXXXXXXXXXXXXXXXXXXX-->
<!-- XXXXXXXXXXXXXXXXXXXXXXXXXXXXXXXXXXXXXXXXXXXXXXXXXXXXXXXXXXXXXXXXXXXXXXXXXXXXXXXXXXXXXXXXXXXXXXXXXXX-->
 <macro name="front_disk_wheel_joint" params=" prefix suffix x y z">
  <joint name="${prefix}_${suffix}_disk_wheel_joint" type="revolute">
      <axis xyz="0 0 1" />
      <parent link="structure"/>
      <child link="${prefix}_${suffix}_disk_wheel"/>
      <origin xyz="${x} ${y} ${z}" />
      <!-- lower and upper limit of the joint in radians velocity=maxvelocity-->
      <limit effort="1000.0" lower="-0.4" upper="0.4" velocity="0.5"/>
  </joint>
 </macro>

 <!-- XXXXXXXXXXXXXXXXXXXXXXXXXXXXXXXXXXXXXXX  disk fixed back  XXXXXXXXXXXXXXXXXXXXXXXXXXXXXXXXXXXXXXXX-->
<!-- XXXXXXXXXXXXXXXXXXXXXXXXXXXXXXXXXXXXXXXXXXXXXXXXXXXXXXXXXXXXXXXXXXXXXXXXXXXXXXXXXXXXXXXXXXXXXXXXXXX-->
 <macro name="back_disk_wheel_joint" params=" prefix suffix x y z">
  <joint name="${prefix}_${suffix}_disk_wheel_joint" type="fixed">
      <parent link="structure"/>
      <child link="${prefix}_${suffix}_disk_wheel"/>
      <origin xyz="${x} ${y} ${z}" />
  </joint>
 </macro>

<!-- XXXXXXXXXXXXXXXXXXXXXXXXXXXXXXXXXXXXXXX   Cameras    XXXXXXXXXXXXXXXXXXXXXXXXXXXXXXXXXXXXXXXXXXXXX-->
<!-- XXXXXXXXXXXXXXXXXXXXXXXXXXXXXXXXXXXXXXXXXXXXXXXXXXXXXXXXXXXXXXXXXXXXXXXXXXXXXXXXXXXXXXXXXXXXXXXXXXX-->

  <macro name="my_camera" params="prefix">  
   <link name="${prefix}_camera">
    <visual>
    <origin xyz="0 0 0" rpy="0 0 0" />
      <geometry>
        <box size="${camera_size} ${camera_size} ${camera_size}"/>
      </geometry>
    </visual>

    <collision>
      <geometry>
      <box size="${camera_size} ${camera_size} ${camera_size}"/>
      </geometry>
        <origin xyz="0 0 0" rpy="0 0 0"  />
    </collision>
        
    <inertial>
      <mass value="${camera_mass}" />
      <origin xyz="0 0 0" rpy="0 0 0"/>
      <inertia ixx="0.0001" ixy="0" ixz="0" iyy="0.0001" iyz="0" izz="0.0001" />
    </inertial>
   </link>

   <gazebo reference="${prefix}_camera">
    <material>Gazebo/Red</material>
    <mu1>0.2</mu1>
    <mu2>0.2</mu2>
   </gazebo>
  </macro>
<!-- XXXXXXXXXXXXXXXXXXXXXXXXXXXXXXXXXXXXXXX   Cameras Joint   XXXXXXXXXXXXXXXXXXXXXXXXXXXXXXXXXXXXXXXXXXXXX-->
<!-- XXXXXXXXXXXXXXXXXXXXXXXXXXXXXXXXXXXXXXXXXXXXXXXXXXXXXXXXXXXXXXXXXXXXXXXXXXXXXXXXXXXXXXXXXXXXXXXXXXX-->
  <macro name="camera_joint" params=" prefix x y z roll pitch yall">
   <joint name="${prefix}_camera_joint" type="fixed">
     <axis xyz="0 1 0" />
     <origin xyz="${x} ${y} ${z}" rpy="${roll} ${pitch} ${yall}"/>
     <parent link="structure"/>
     <child link="${prefix}_camera"/>
   </joint>
  </macro>

 </robot>
